<?xml version="1.0"?>
<robot xmlns:xacro="http://ros.org/wiki/xacro">

  <!-- Constants -->
  <xacro:property name="visual_mesh_scale" value="1.0 1.0 1.0"/>
  <xacro:property name="collision_mesh_scale" value="1.0 1.0 1.0"/>


  <xacro:include filename="$(find catchrobo_description)/urdf/arm.transmission.xacro"/>

  <!-- Link & Joint -->
  <xacro:macro name="scara" params="prefix parent *joint_origin">

    <joint name="${prefix}arm/root" type="fixed">
      <xacro:insert_block name="joint_origin" />
      <parent link="${parent}" />
      <child link="${prefix}arm/link0" />
    </joint>
    
    <link name="${prefix}arm/link0">
      <visual>
        <geometry>
          <mesh filename="package://catchrobo_description/mesh/scara/visual/link0.stl" scale="${visual_mesh_scale}"/>
        </geometry>
        <material name="white"/>
      </visual>
      <collision>
        <geometry>
          <mesh filename="package://catchrobo_description/mesh/scara/collision/link0.stl" scale="${collision_mesh_scale}"/>
        </geometry>
      </collision>
    </link>

    <joint name="${prefix}arm/joint1" type="revolute">
      <parent link="${prefix}arm/link0"/>
      <child link="${prefix}arm/link1"/>
      <origin xyz="0 0 0.1062" rpy="0 0 0"/>
      <axis xyz="0 0 1"/>
      <limit lower="${-160*M_PI/180}" upper="${160*M_PI/180}" effort="6"
              velocity="5" acceleration="5"/>
    </joint>  

    <link name="${prefix}arm/link1">
      <visual>
        <geometry>
          <mesh filename="package://catchrobo_description/mesh/scara/visual/link1.stl" scale="${visual_mesh_scale}"/>
        </geometry>
        <material name="white"/>
      </visual>
      <collision>
        <geometry>
          <mesh filename="package://catchrobo_description/mesh/scara/collision/link1.stl" scale="${collision_mesh_scale}"/>
        </geometry>
      </collision>
    </link>

    <joint name="${prefix}arm/joint2" type="revolute">
      <parent link="${prefix}arm/link1"/>
      <child link="${prefix}arm/link2"/>
      <origin xyz="0.45 0 0.026" rpy="0 0 0"/>
      <axis xyz="0 0 1"/>
      <limit lower="${-160*M_PI/180}" upper="${160*M_PI/180}" effort="6"
              velocity="5" acceleration="5"/>
    </joint>

    <link name="${prefix}arm/link2">
      <visual>
        <geometry>
          <mesh filename="package://catchrobo_description/mesh/scara/visual/link2.stl" scale="${visual_mesh_scale}"/>
        </geometry>
        <material name="white"/>
      </visual>
      <collision>
        <geometry>
          <mesh filename="package://catchrobo_description/mesh/scara/collision/link2.stl" scale="${collision_mesh_scale}"/>
        </geometry>
      </collision>
    </link>

    <joint name="${prefix}arm/joint3" type="revolute">
      <parent link="${prefix}arm/link2"/>
      <child link="${prefix}arm/link3"/>
      <origin xyz="0.45 0 0" rpy="0 0 0"/>
      <axis xyz="0 0 1"/>
      <limit lower="${-160*M_PI/180}" upper="${160*M_PI/180}" effort="6"
              velocity="5" acceleration="5"/>
    </joint>

    <link name="${prefix}arm/link3">
      <visual>
        <geometry>
          <mesh filename="package://catchrobo_description/mesh/scara/visual/link3.stl" scale="${visual_mesh_scale}"/>
        </geometry>
        <material name="white"/>
      </visual>
      <collision>
        <geometry>
          <mesh filename="package://catchrobo_description/mesh/scara/collision/link3.stl" scale="${collision_mesh_scale}"/>
        </geometry>
      </collision>
    </link>

    <joint name="${prefix}arm/joint4" type="prismatic">
      <parent link="${prefix}arm/link3"/>
      <child link="${prefix}arm/link4"/>
      <origin xyz="0 0 -0.0403" rpy="0 0 0"/>
      <axis xyz="0 0 1"/>
      <limit lower="0" upper="-0.25" effort="6"
              velocity="5" acceleration="5"/>
    </joint>

    <link name="${prefix}arm/link4">
      <visual>
        <geometry>
          <mesh filename="package://catchrobo_description/mesh/scara/visual/link4.stl" scale="${visual_mesh_scale}"/>
        </geometry>
        <material name="white"/>
      </visual>
      <collision>
        <geometry>
          <mesh filename="package://catchrobo_description/mesh/scara/collision/link4.stl" scale="${collision_mesh_scale}"/>
        </geometry>
      </collision>
    </link>

    <joint name="${prefix}arm/joint_tip" type="fixed">
      <parent link="${prefix}arm/link4"/>
      <child link="${prefix}arm/link_tip"/>
      <origin xyz="0 0 0" rpy="0 ${180*M_PI/180} 0"/>
    </joint>
    <link name="${prefix}arm/link_tip"/>
  
  </xacro:macro>
</robot>